<sdf version='1.7'>
  <model name='a1_description'>
    <link name='body'>
      <inertial>
        <pose>0.022296 0.002 -0.0005 0 -0 0</pose>
        <mass>5.205</mass>
        <inertia>
          <ixx>0.0169129</ixx>
          <ixy>-0.000229721</ixy>
          <ixz>-0.000294518</ixz>
          <iyy>0.0631101</iyy>
          <iyz>-4.18721e-05</iyz>
          <izz>0.0717552</izz>
        </inertia>
      </inertial>
      <collision name='body_collision_collision'>
        <pose>0 0 0 0 -0 0</pose>
        <geometry>
          <box>
            <size>0.3762 0.0935 0.114</size>
          </box>
        </geometry>
        <surface>
          <contact>
            <ode/>
          </contact>
          <friction>
            <ode/>
          </friction>
        </surface>
      </collision>
      <collision name='body_fixed_joint_lump__imu_link_collision_1'>
        <pose>0 0 0 0 -0 0</pose>
        <geometry>
          <box>
            <size>0.001 0.001 0.001</size>
          </box>
        </geometry>
        <surface>
          <contact>
            <ode/>
          </contact>
          <friction>
            <ode>
              <mu>0.2</mu>
              <mu2>0.2</mu2>
            </ode>
          </friction>
        </surface>
      </collision>
      <visual name='body_visual'>
        <pose>0 0 0 0 -0 0</pose>
        <geometry>
          <box>
            <size>0.001 0.001 0.001</size>
          </box>
        </geometry>
        <material>
          <script>
            <name>Gazebo/Green</name>
            <uri>file://media/materials/scripts/gazebo.material</uri>
          </script>
        </material>
      </visual>
      <visual name='body_visual_visual_1'>
        <pose>0 0 0 0 -0 0</pose>
        <geometry>
          <mesh>
            <scale>1 1 1</scale>
            <uri>model://a1_description/meshes/trunk.dae</uri>
          </mesh>
        </geometry>
        <material>
          <script>
            <name>Gazebo/Green</name>
            <uri>file://media/materials/scripts/gazebo.material</uri>
          </script>
        </material>
      </visual>
      <visual name='body_fixed_joint_lump__imu_link_visual_2'>
        <pose>0 0 0 0 -0 0</pose>
        <geometry>
          <box>
            <size>0.001 0.001 0.001</size>
          </box>
        </geometry>
        <material>
          <script>
            <name>Gazebo/Red</name>
            <uri>file://media/materials/scripts/gazebo.material</uri>
          </script>
        </material>
      </visual>
      <gravity>1</gravity>
      <gravity>1</gravity>
      <sensor name='imu_sensor' type='imu'>
        <always_on>1</always_on>
        <update_rate>1000</update_rate>
        <visualize>1</visualize>
        <topic>__default_topic__</topic>
        <plugin name='imu_plugin' filename='libgazebo_ros_imu_sensor.so'>
          <topicName>trunk_imu</topicName>
          <bodyName>imu_link</bodyName>
          <updateRateHZ>1000.0</updateRateHZ>
          <gaussianNoise>0.0</gaussianNoise>
          <xyzOffset>0 0 0</xyzOffset>
          <rpyOffset>0 0 0</rpyOffset>
          <frameName>imu_link</frameName>
        </plugin>
        <pose>0 0 0 0 -0 0</pose>
      </sensor>
    </link>
    <joint name='10' type='revolute'>
      <pose relative_to='body'>0.1881 -0.04675 0 0 -0 0</pose>
      <parent>body</parent>
      <child>hip2</child>
      <axis>
        <xyz>1 0 0</xyz>
        <limit>
          <lower>-0.0150622</lower>
          <upper>0.0150622</upper>
          <effort>23.7</effort>
          <velocity>30.1</velocity>
        </limit>
        <dynamics>
          <damping>0.01</damping>
          <friction>0.2</friction>
          <spring_reference>0</spring_reference>
          <spring_stiffness>0</spring_stiffness>
        </dynamics>
      </axis>
    </joint>
    <link name='hip2'>
      <pose relative_to='10'>0 0 0 0 -0 0</pose>
      <inertial>
        <pose>-0.005657 0.008752 -0.000102 0 -0 0</pose>
        <mass>0.591</mass>
        <inertia>
          <ixx>0.000334008</ixx>
          <ixy>1.08261e-05</ixy>
          <ixz>1.29073e-06</ixz>
          <iyy>0.000619101</iyy>
          <iyz>-1.64319e-06</iyz>
          <izz>0.000400576</izz>
        </inertia>
      </inertial>
      <collision name='hip2_collision_collision'>
        <pose>0 0 0 1.5708 -0 0</pose>
        <geometry>
          <cylinder>
            <length>0.04</length>
            <radius>0.046</radius>
          </cylinder>
        </geometry>
        <surface>
          <contact>
            <ode/>
          </contact>
          <friction>
            <ode>
              <mu>0.2</mu>
              <mu2>0.2</mu2>
            </ode>
          </friction>
        </surface>
      </collision>
      <collision name='hip2_fixed_joint_lump__thigh_shoulder2_collision_1'>
        <pose>0 -0.096 0 1.5708 -0 0</pose>
        <geometry>
          <cylinder>
            <length>0.032</length>
            <radius>0.041</radius>
          </cylinder>
        </geometry>
      </collision>
      <visual name='hip2_visual_visual'>
        <pose>0 0 0 3.14159 -0 0</pose>
        <geometry>
          <mesh>
            <scale>1 1 1</scale>
            <uri>model://a1_description/meshes/hip.dae</uri>
          </mesh>
        </geometry>
        <material>
          <script>
            <name>Gazebo/DarkGrey</name>
            <uri>file://media/materials/scripts/gazebo.material</uri>
          </script>
        </material>
      </visual>
    </link>
    <joint name='4' type='revolute'>
      <pose relative_to='hip2'>0 -0.08 0 0 1.5708 0</pose>
      <parent>hip2</parent>
      <child>upper2</child>
      <axis>
        <xyz>0 -1 0</xyz>
        <limit>
          <lower>-0.011973</lower>
          <upper>0.0785573</upper>
          <effort>23.7</effort>
          <velocity>30.1</velocity>
        </limit>
        <dynamics>
          <damping>0.01</damping>
          <friction>0.2</friction>
          <spring_reference>0</spring_reference>
          <spring_stiffness>0</spring_stiffness>
        </dynamics>
      </axis>
    </joint>
    <link name='upper2'>
      <pose relative_to='4'>0 0 0 0 -0 0</pose>
      <inertial>
        <pose>-0.003342 0.018054 -0.033451 0 -0 0</pose>
        <mass>0.92</mass>
        <inertia>
          <ixx>0.00443176</ixx>
          <ixy>-5.74968e-05</ixy>
          <ixz>-0.000218457</ixz>
          <iyy>0.00448567</iyy>
          <iyz>-0.000572001</iyz>
          <izz>0.000740309</izz>
        </inertia>
      </inertial>
      <collision name='upper2_collision_collision'>
        <pose>0 0 -0.1065 0 1.5708 0</pose>
        <geometry>
          <box>
            <size>0.213 0.0245 0.034</size>
          </box>
        </geometry>
        <surface>
          <contact>
            <ode>
              <kp>1e+06</kp>
              <kd>1</kd>
            </ode>
          </contact>
          <friction>
            <ode>
              <mu>0.2</mu>
              <mu2>0.2</mu2>
            </ode>
          </friction>
        </surface>
      </collision>
      <visual name='upper2_visual_visual'>
        <pose>0 0 0 0 -0 0</pose>
        <geometry>
          <mesh>
            <scale>1 1 1</scale>
            <uri>model://a1_description/meshes/thigh_mirror.dae</uri>
          </mesh>
        </geometry>
        <material>
          <script>
            <name>Gazebo/DarkGrey</name>
            <uri>file://media/materials/scripts/gazebo.material</uri>
          </script>
        </material>
      </visual>
      <self_collide>0</self_collide>
    </link>
    <joint name='5' type='revolute'>
      <pose relative_to='upper2'>0 0 -0.213 3.14159 -0 3.14159</pose>
      <parent>upper2</parent>
      <child>lower2</child>
      <axis>
        <xyz>0 1 0</xyz>
        <limit>
          <lower>-0.0491834</lower>
          <upper>-0.0154985</upper>
          <effort>35.55</effort>
          <velocity>20.06</velocity>
        </limit>
        <dynamics>
          <damping>0.01</damping>
          <friction>0.2</friction>
          <spring_reference>0</spring_reference>
          <spring_stiffness>0</spring_stiffness>
        </dynamics>
      </axis>
    </joint>
    <link name='lower2'>
      <pose relative_to='5'>0 0 0 0 -0 0</pose>
      <inertial>
        <pose>0.004299 0.000977 -0.146197 0 -0 0</pose>
        <mass>0.195862</mass>
        <inertia>
          <ixx>0.00148448</ixx>
          <ixy>-6.18827e-07</ixy>
          <ixz>-1.77209e-05</ixz>
          <iyy>0.00149764</iyy>
          <iyz>-3.56626e-06</iyz>
          <izz>3.60683e-05</izz>
        </inertia>
      </inertial>
      <collision name='lower2_collision_collision'>
        <pose>0 0 -0.1065 0 1.5708 0</pose>
        <geometry>
          <box>
            <size>0.213 0.016 0.016</size>
          </box>
        </geometry>
        <surface>
          <contact>
            <ode/>
          </contact>
          <friction>
            <ode>
              <mu>0.2</mu>
              <mu2>0.2</mu2>
            </ode>
          </friction>
        </surface>
      </collision>
      <collision name='lower2_fixed_joint_lump__toe2_collision_collision_1'>
        <pose>0 0 -0.213 0 -0 0</pose>
        <geometry>
          <sphere>
            <radius>0.02</radius>
          </sphere>
        </geometry>
        <surface>
          <contact>
            <ode>
              <kp>1e+06</kp>
              <kd>1</kd>
            </ode>
          </contact>
          <friction>
            <ode>
              <mu>0.6</mu>
              <mu2>0.6</mu2>
            </ode>
          </friction>
        </surface>
      </collision>
      <visual name='lower2_visual_visual'>
        <pose>0 0 0 0 -0 0</pose>
        <geometry>
          <mesh>
            <scale>1 1 1</scale>
            <uri>model://a1_description/meshes/calf.dae</uri>
          </mesh>
        </geometry>
      </visual>
      <visual name='lower2_fixed_joint_lump__toe2_visual_visual_1'>
        <pose>0 0 -0.213 0 -0 0</pose>
        <geometry>
          <sphere>
            <radius>0.01</radius>
          </sphere>
        </geometry>
        <material>
          <script>
            <name>Gazebo/DarkGrey</name>
            <uri>file://media/materials/scripts/gazebo.material</uri>
          </script>
        </material>
      </visual>
      <self_collide>0</self_collide>
      <sensor name='toe2_contact' type='contact'>
        <plugin name='toe2_plugin' filename='libgazebo_ros_bumper.so'>
          <alwaysOn>1</alwaysOn>
          <updateRate>500</updateRate>
          <bumperTopicName>gazebo/toe2_contact_state</bumperTopicName>
          <frameName>world</frameName>
        </plugin>
        <contact>
          <collision>lower2_collision_toe2</collision>
          <topic>__default_topic__</topic>
        </contact>
        <update_rate>500</update_rate>
        <pose>0 0 -0.213 0 -0 0</pose>
      </sensor>
      <self_collide>0</self_collide>
    </link>
    <joint name='11' type='revolute'>
      <pose relative_to='body'>-0.1881 -0.04675 0 0 -0 0</pose>
      <parent>body</parent>
      <child>hip3</child>
      <axis>
        <xyz>1 0 0</xyz>
        <limit>
          <lower>-0.0150622</lower>
          <upper>0.0150622</upper>
          <effort>23.7</effort>
          <velocity>30.1</velocity>
        </limit>
        <dynamics>
          <damping>0.01</damping>
          <friction>0.2</friction>
          <spring_reference>0</spring_reference>
          <spring_stiffness>0</spring_stiffness>
        </dynamics>
      </axis>
    </joint>
    <link name='hip3'>
      <pose relative_to='11'>0 0 0 0 -0 0</pose>
      <inertial>
        <pose>0.005657 0.008752 -0.000102 0 -0 0</pose>
        <mass>0.591</mass>
        <inertia>
          <ixx>0.000334008</ixx>
          <ixy>-1.08261e-05</ixy>
          <ixz>-1.29073e-06</ixz>
          <iyy>0.000619101</iyy>
          <iyz>-1.64319e-06</iyz>
          <izz>0.000400576</izz>
        </inertia>
      </inertial>
      <collision name='hip3_collision_collision'>
        <pose>0 0 0 1.5708 -0 0</pose>
        <geometry>
          <cylinder>
            <length>0.04</length>
            <radius>0.046</radius>
          </cylinder>
        </geometry>
        <surface>
          <contact>
            <ode/>
          </contact>
          <friction>
            <ode>
              <mu>0.2</mu>
              <mu2>0.2</mu2>
            </ode>
          </friction>
        </surface>
      </collision>
      <collision name='hip3_fixed_joint_lump__thigh_shoulder3_collision_1'>
        <pose>0 -0.096 0 1.5708 -0 0</pose>
        <geometry>
          <cylinder>
            <length>0.032</length>
            <radius>0.041</radius>
          </cylinder>
        </geometry>
      </collision>
      <visual name='hip3_visual_visual'>
        <pose>0 0 0 -0 0 3.14159</pose>
        <geometry>
          <mesh>
            <scale>1 1 1</scale>
            <uri>model://a1_description/meshes/hip.dae</uri>
          </mesh>
        </geometry>
        <material>
          <script>
            <name>Gazebo/DarkGrey</name>
            <uri>file://media/materials/scripts/gazebo.material</uri>
          </script>
        </material>
      </visual>
    </link>
    <joint name='6' type='revolute'>
      <pose relative_to='hip3'>0 -0.08 0 0 1.5708 0</pose>
      <parent>hip3</parent>
      <child>upper3</child>
      <axis>
        <xyz>0 -1 0</xyz>
        <limit>
          <lower>-0.011973</lower>
          <upper>0.0785573</upper>
          <effort>23.7</effort>
          <velocity>30.1</velocity>
        </limit>
        <dynamics>
          <damping>0.01</damping>
          <friction>0.2</friction>
          <spring_reference>0</spring_reference>
          <spring_stiffness>0</spring_stiffness>
        </dynamics>
      </axis>
    </joint>
    <link name='upper3'>
      <pose relative_to='6'>0 0 0 0 -0 0</pose>
      <inertial>
        <pose>-0.003342 0.018054 -0.033451 0 -0 0</pose>
        <mass>0.92</mass>
        <inertia>
          <ixx>0.00443176</ixx>
          <ixy>-5.74968e-05</ixy>
          <ixz>-0.000218457</ixz>
          <iyy>0.00448567</iyy>
          <iyz>-0.000572001</iyz>
          <izz>0.000740309</izz>
        </inertia>
      </inertial>
      <collision name='upper3_collision_collision'>
        <pose>0 0 -0.1065 0 1.5708 0</pose>
        <geometry>
          <box>
            <size>0.213 0.0245 0.034</size>
          </box>
        </geometry>
        <surface>
          <contact>
            <ode>
              <kp>1e+06</kp>
              <kd>1</kd>
            </ode>
          </contact>
          <friction>
            <ode>
              <mu>0.2</mu>
              <mu2>0.2</mu2>
            </ode>
          </friction>
        </surface>
      </collision>
      <visual name='upper3_visual_visual'>
        <pose>0 0 0 0 -0 0</pose>
        <geometry>
          <mesh>
            <scale>1 1 1</scale>
            <uri>model://a1_description/meshes/thigh_mirror.dae</uri>
          </mesh>
        </geometry>
        <material>
          <script>
            <name>Gazebo/DarkGrey</name>
            <uri>file://media/materials/scripts/gazebo.material</uri>
          </script>
        </material>
      </visual>
      <self_collide>0</self_collide>
    </link>
    <joint name='7' type='revolute'>
      <pose relative_to='upper3'>0 0 -0.213 3.14159 -0 3.14159</pose>
      <parent>upper3</parent>
      <child>lower3</child>
      <axis>
        <xyz>0 1 0</xyz>
        <limit>
          <lower>-0.0491834</lower>
          <upper>-0.0154985</upper>
          <effort>35.55</effort>
          <velocity>20.06</velocity>
        </limit>
        <dynamics>
          <damping>0.01</damping>
          <friction>0.2</friction>
          <spring_reference>0</spring_reference>
          <spring_stiffness>0</spring_stiffness>
        </dynamics>
      </axis>
    </joint>
    <link name='lower3'>
      <pose relative_to='7'>0 0 0 0 -0 0</pose>
      <inertial>
        <pose>0.004299 0.000977 -0.146197 0 -0 0</pose>
        <mass>0.195862</mass>
        <inertia>
          <ixx>0.00148448</ixx>
          <ixy>-6.18827e-07</ixy>
          <ixz>-1.77209e-05</ixz>
          <iyy>0.00149764</iyy>
          <iyz>-3.56626e-06</iyz>
          <izz>3.60683e-05</izz>
        </inertia>
      </inertial>
      <collision name='lower3_collision_collision'>
        <pose>0 0 -0.1065 0 1.5708 0</pose>
        <geometry>
          <box>
            <size>0.213 0.016 0.016</size>
          </box>
        </geometry>
        <surface>
          <contact>
            <ode/>
          </contact>
          <friction>
            <ode>
              <mu>0.2</mu>
              <mu2>0.2</mu2>
            </ode>
          </friction>
        </surface>
      </collision>
      <collision name='lower3_fixed_joint_lump__toe3_collision_collision_1'>
        <pose>0 0 -0.213 0 -0 0</pose>
        <geometry>
          <sphere>
            <radius>0.02</radius>
          </sphere>
        </geometry>
        <surface>
          <contact>
            <ode>
              <kp>1e+06</kp>
              <kd>1</kd>
            </ode>
          </contact>
          <friction>
            <ode>
              <mu>0.6</mu>
              <mu2>0.6</mu2>
            </ode>
          </friction>
        </surface>
      </collision>
      <visual name='lower3_visual_visual'>
        <pose>0 0 0 0 -0 0</pose>
        <geometry>
          <mesh>
            <scale>1 1 1</scale>
            <uri>model://a1_description/meshes/calf.dae</uri>
          </mesh>
        </geometry>
      </visual>
      <visual name='lower3_fixed_joint_lump__toe3_visual_visual_1'>
        <pose>0 0 -0.213 0 -0 0</pose>
        <geometry>
          <sphere>
            <radius>0.01</radius>
          </sphere>
        </geometry>
        <material>
          <script>
            <name>Gazebo/DarkGrey</name>
            <uri>file://media/materials/scripts/gazebo.material</uri>
          </script>
        </material>
      </visual>
      <self_collide>0</self_collide>
      <sensor name='toe3_contact' type='contact'>
        <plugin name='toe3_plugin' filename='libgazebo_ros_bumper.so'>
          <alwaysOn>1</alwaysOn>
          <updateRate>500</updateRate>
          <bumperTopicName>gazebo/toe3_contact_state</bumperTopicName>
          <frameName>world</frameName>
        </plugin>
        <contact>
          <collision>lower3_collision_toe3</collision>
          <topic>__default_topic__</topic>
        </contact>
        <update_rate>500</update_rate>
        <pose>0 0 -0.213 0 -0 0</pose>
      </sensor>
      <self_collide>0</self_collide>
    </link>
    <joint name='8' type='revolute'>
      <pose relative_to='body'>0.1881 0.04675 0 0 -0 0</pose>
      <parent>body</parent>
      <child>hip0</child>
      <axis>
        <xyz>1 0 0</xyz>
        <limit>
          <lower>-0.0150622</lower>
          <upper>0.0150622</upper>
          <effort>23.7</effort>
          <velocity>30.1</velocity>
        </limit>
        <dynamics>
          <damping>0.01</damping>
          <friction>0.2</friction>
          <spring_reference>0</spring_reference>
          <spring_stiffness>0</spring_stiffness>
        </dynamics>
      </axis>
    </joint>
    <link name='hip0'>
      <pose relative_to='8'>0 0 0 0 -0 0</pose>
      <inertial>
        <pose>-0.005657 -0.008752 -0.000102 0 -0 0</pose>
        <mass>0.591</mass>
        <inertia>
          <ixx>0.000334008</ixx>
          <ixy>-1.08261e-05</ixy>
          <ixz>1.29073e-06</ixz>
          <iyy>0.000619101</iyy>
          <iyz>1.64319e-06</iyz>
          <izz>0.000400576</izz>
        </inertia>
      </inertial>
      <collision name='hip0_collision_collision'>
        <pose>0 0 0 1.5708 -0 0</pose>
        <geometry>
          <cylinder>
            <length>0.04</length>
            <radius>0.046</radius>
          </cylinder>
        </geometry>
        <surface>
          <contact>
            <ode/>
          </contact>
          <friction>
            <ode>
              <mu>0.2</mu>
              <mu2>0.2</mu2>
            </ode>
          </friction>
        </surface>
      </collision>
      <collision name='hip0_fixed_joint_lump__thigh_shoulder0_collision_1'>
        <pose>0 0.096 0 1.5708 -0 0</pose>
        <geometry>
          <cylinder>
            <length>0.032</length>
            <radius>0.041</radius>
          </cylinder>
        </geometry>
      </collision>
      <visual name='hip0_visual_visual'>
        <pose>0 0 0 0 -0 0</pose>
        <geometry>
          <mesh>
            <scale>1 1 1</scale>
            <uri>model://a1_description/meshes/hip.dae</uri>
          </mesh>
        </geometry>
        <material>
          <script>
            <name>Gazebo/DarkGrey</name>
            <uri>file://media/materials/scripts/gazebo.material</uri>
          </script>
        </material>
      </visual>
    </link>
    <joint name='0' type='revolute'>
      <pose relative_to='hip0'>0 0.08 0 0 1.5708 0</pose>
      <parent>hip0</parent>
      <child>upper0</child>
      <axis>
        <xyz>0 -1 0</xyz>
        <limit>
          <lower>-0.011973</lower>
          <upper>0.0785573</upper>
          <effort>23.7</effort>
          <velocity>30.1</velocity>
        </limit>
        <dynamics>
          <damping>0.01</damping>
          <friction>0.2</friction>
          <spring_reference>0</spring_reference>
          <spring_stiffness>0</spring_stiffness>
        </dynamics>
      </axis>
    </joint>
    <link name='upper0'>
      <pose relative_to='0'>0 0 0 0 -0 0</pose>
      <inertial>
        <pose>-0.003342 -0.018054 -0.033451 0 -0 0</pose>
        <mass>0.92</mass>
        <inertia>
          <ixx>0.00443176</ixx>
          <ixy>5.74968e-05</ixy>
          <ixz>-0.000218457</ixz>
          <iyy>0.00448567</iyy>
          <iyz>0.000572001</iyz>
          <izz>0.000740309</izz>
        </inertia>
      </inertial>
      <collision name='upper0_collision_collision'>
        <pose>0 0 -0.1065 0 1.5708 0</pose>
        <geometry>
          <box>
            <size>0.213 0.0245 0.034</size>
          </box>
        </geometry>
        <surface>
          <contact>
            <ode>
              <kp>1e+06</kp>
              <kd>1</kd>
            </ode>
          </contact>
          <friction>
            <ode>
              <mu>0.2</mu>
              <mu2>0.2</mu2>
            </ode>
          </friction>
        </surface>
      </collision>
      <visual name='upper0_visual_visual'>
        <pose>0 0 0 0 -0 0</pose>
        <geometry>
          <mesh>
            <scale>1 1 1</scale>
            <uri>model://a1_description/meshes/thigh.dae</uri>
          </mesh>
        </geometry>
        <material>
          <script>
            <name>Gazebo/DarkGrey</name>
            <uri>file://media/materials/scripts/gazebo.material</uri>
          </script>
        </material>
      </visual>
      <self_collide>0</self_collide>
    </link>
    <joint name='1' type='revolute'>
      <pose relative_to='upper0'>0 0 -0.213 3.14159 -0 3.14159</pose>
      <parent>upper0</parent>
      <child>lower0</child>
      <axis>
        <xyz>0 1 0</xyz>
        <limit>
          <lower>-0.0491834</lower>
          <upper>-0.0154985</upper>
          <effort>35.55</effort>
          <velocity>20.06</velocity>
        </limit>
        <dynamics>
          <damping>0.01</damping>
          <friction>0.2</friction>
          <spring_reference>0</spring_reference>
          <spring_stiffness>0</spring_stiffness>
        </dynamics>
      </axis>
    </joint>
    <link name='lower0'>
      <pose relative_to='1'>0 0 0 0 -0 0</pose>
      <inertial>
        <pose>0.004299 0.000977 -0.146197 0 -0 0</pose>
        <mass>0.195862</mass>
        <inertia>
          <ixx>0.00148448</ixx>
          <ixy>-6.18827e-07</ixy>
          <ixz>-1.77209e-05</ixz>
          <iyy>0.00149764</iyy>
          <iyz>-3.56626e-06</iyz>
          <izz>3.60683e-05</izz>
        </inertia>
      </inertial>
      <collision name='lower0_collision_collision'>
        <pose>0 0 -0.1065 0 1.5708 0</pose>
        <geometry>
          <box>
            <size>0.213 0.016 0.016</size>
          </box>
        </geometry>
        <surface>
          <contact>
            <ode/>
          </contact>
          <friction>
            <ode>
              <mu>0.2</mu>
              <mu2>0.2</mu2>
            </ode>
          </friction>
        </surface>
      </collision>
      <collision name='lower0_fixed_joint_lump__toe0_collision_collision_1'>
        <pose>0 0 -0.213 0 -0 0</pose>
        <geometry>
          <sphere>
            <radius>0.02</radius>
          </sphere>
        </geometry>
        <surface>
          <contact>
            <ode>
              <kp>1e+06</kp>
              <kd>1</kd>
            </ode>
          </contact>
          <friction>
            <ode>
              <mu>0.6</mu>
              <mu2>0.6</mu2>
            </ode>
          </friction>
        </surface>
      </collision>
      <visual name='lower0_visual_visual'>
        <pose>0 0 0 0 -0 0</pose>
        <geometry>
          <mesh>
            <scale>1 1 1</scale>
            <uri>model://a1_description/meshes/calf.dae</uri>
          </mesh>
        </geometry>
      </visual>
      <visual name='lower0_fixed_joint_lump__toe0_visual_visual_1'>
        <pose>0 0 -0.213 0 -0 0</pose>
        <geometry>
          <sphere>
            <radius>0.01</radius>
          </sphere>
        </geometry>
        <material>
          <script>
            <name>Gazebo/DarkGrey</name>
            <uri>file://media/materials/scripts/gazebo.material</uri>
          </script>
        </material>
      </visual>
      <self_collide>0</self_collide>
      <sensor name='toe0_contact' type='contact'>
        <plugin name='toe0_plugin' filename='libgazebo_ros_bumper.so'>
          <alwaysOn>1</alwaysOn>
          <updateRate>500</updateRate>
          <bumperTopicName>gazebo/toe0_contact_state</bumperTopicName>
          <frameName>world</frameName>
        </plugin>
        <contact>
          <collision>lower0_collision_toe0</collision>
          <topic>__default_topic__</topic>
        </contact>
        <update_rate>500</update_rate>
        <pose>0 0 -0.213 0 -0 0</pose>
      </sensor>
      <self_collide>0</self_collide>
    </link>
    <joint name='9' type='revolute'>
      <pose relative_to='body'>-0.1881 0.04675 0 0 -0 0</pose>
      <parent>body</parent>
      <child>hip1</child>
      <axis>
        <xyz>1 0 0</xyz>
        <limit>
          <lower>-0.0150622</lower>
          <upper>0.0150622</upper>
          <effort>23.7</effort>
          <velocity>30.1</velocity>
        </limit>
        <dynamics>
          <damping>0.01</damping>
          <friction>0.2</friction>
          <spring_reference>0</spring_reference>
          <spring_stiffness>0</spring_stiffness>
        </dynamics>
      </axis>
    </joint>
    <link name='hip1'>
      <pose relative_to='9'>0 0 0 0 -0 0</pose>
      <inertial>
        <pose>0.005657 -0.008752 -0.000102 0 -0 0</pose>
        <mass>0.591</mass>
        <inertia>
          <ixx>0.000334008</ixx>
          <ixy>1.08261e-05</ixy>
          <ixz>-1.29073e-06</ixz>
          <iyy>0.000619101</iyy>
          <iyz>1.64319e-06</iyz>
          <izz>0.000400576</izz>
        </inertia>
      </inertial>
      <collision name='hip1_collision_collision'>
        <pose>0 0 0 1.5708 -0 0</pose>
        <geometry>
          <cylinder>
            <length>0.04</length>
            <radius>0.046</radius>
          </cylinder>
        </geometry>
        <surface>
          <contact>
            <ode/>
          </contact>
          <friction>
            <ode>
              <mu>0.2</mu>
              <mu2>0.2</mu2>
            </ode>
          </friction>
        </surface>
      </collision>
      <collision name='hip1_fixed_joint_lump__thigh_shoulder1_collision_1'>
        <pose>0 0.096 0 1.5708 -0 0</pose>
        <geometry>
          <cylinder>
            <length>0.032</length>
            <radius>0.041</radius>
          </cylinder>
        </geometry>
      </collision>
      <visual name='hip1_visual_visual'>
        <pose>0 0 0 3.14159 0 3.14159</pose>
        <geometry>
          <mesh>
            <scale>1 1 1</scale>
            <uri>model://a1_description/meshes/hip.dae</uri>
          </mesh>
        </geometry>
        <material>
          <script>
            <name>Gazebo/DarkGrey</name>
            <uri>file://media/materials/scripts/gazebo.material</uri>
          </script>
        </material>
      </visual>
    </link>
    <joint name='2' type='revolute'>
      <pose relative_to='hip1'>0 0.08 0 0 1.5708 0</pose>
      <parent>hip1</parent>
      <child>upper1</child>
      <axis>
        <xyz>0 -1 0</xyz>
        <limit>
          <lower>-0.011973</lower>
          <upper>0.0785573</upper>
          <effort>23.7</effort>
          <velocity>30.1</velocity>
        </limit>
        <dynamics>
          <damping>0.01</damping>
          <friction>0.2</friction>
          <spring_reference>0</spring_reference>
          <spring_stiffness>0</spring_stiffness>
        </dynamics>
      </axis>
    </joint>
    <link name='upper1'>
      <pose relative_to='2'>0 0 0 0 -0 0</pose>
      <inertial>
        <pose>-0.003342 -0.018054 -0.033451 0 -0 0</pose>
        <mass>0.92</mass>
        <inertia>
          <ixx>0.00443176</ixx>
          <ixy>5.74968e-05</ixy>
          <ixz>-0.000218457</ixz>
          <iyy>0.00448567</iyy>
          <iyz>0.000572001</iyz>
          <izz>0.000740309</izz>
        </inertia>
      </inertial>
      <collision name='upper1_collision_collision'>
        <pose>0 0 -0.1065 0 1.5708 0</pose>
        <geometry>
          <box>
            <size>0.213 0.0245 0.034</size>
          </box>
        </geometry>
        <surface>
          <contact>
            <ode>
              <kp>1e+06</kp>
              <kd>1</kd>
            </ode>
          </contact>
          <friction>
            <ode>
              <mu>0.2</mu>
              <mu2>0.2</mu2>
            </ode>
          </friction>
        </surface>
      </collision>
      <visual name='upper1_visual_visual'>
        <pose>0 0 0 0 -0 0</pose>
        <geometry>
          <mesh>
            <scale>1 1 1</scale>
            <uri>model://a1_description/meshes/thigh.dae</uri>
          </mesh>
        </geometry>
        <material>
          <script>
            <name>Gazebo/DarkGrey</name>
            <uri>file://media/materials/scripts/gazebo.material</uri>
          </script>
        </material>
      </visual>
      <self_collide>0</self_collide>
    </link>
    <joint name='3' type='revolute'>
      <pose relative_to='upper1'>0 0 -0.213 3.14159 -0 3.14159</pose>
      <parent>upper1</parent>
      <child>lower1</child>
      <axis>
        <xyz>0 1 0</xyz>
        <limit>
          <lower>-0.0491834</lower>
          <upper>-0.0154985</upper>
          <effort>35.55</effort>
          <velocity>20.06</velocity>
        </limit>
        <dynamics>
          <damping>0.01</damping>
          <friction>0.2</friction>
          <spring_reference>0</spring_reference>
          <spring_stiffness>0</spring_stiffness>
        </dynamics>
      </axis>
    </joint>
    <link name='lower1'>
      <pose relative_to='3'>0 0 0 0 -0 0</pose>
      <inertial>
        <pose>0.004299 0.000977 -0.146197 0 -0 0</pose>
        <mass>0.195862</mass>
        <inertia>
          <ixx>0.00148448</ixx>
          <ixy>-6.18827e-07</ixy>
          <ixz>-1.77209e-05</ixz>
          <iyy>0.00149764</iyy>
          <iyz>-3.56626e-06</iyz>
          <izz>3.60683e-05</izz>
        </inertia>
      </inertial>
      <collision name='lower1_collision_collision'>
        <pose>0 0 -0.1065 0 1.5708 0</pose>
        <geometry>
          <box>
            <size>0.213 0.016 0.016</size>
          </box>
        </geometry>
        <surface>
          <contact>
            <ode/>
          </contact>
          <friction>
            <ode>
              <mu>0.2</mu>
              <mu2>0.2</mu2>
            </ode>
          </friction>
        </surface>
      </collision>
      <collision name='lower1_fixed_joint_lump__toe1_collision_collision_1'>
        <pose>0 0 -0.213 0 -0 0</pose>
        <geometry>
          <sphere>
            <radius>0.02</radius>
          </sphere>
        </geometry>
        <surface>
          <contact>
            <ode>
              <kp>1e+06</kp>
              <kd>1</kd>
            </ode>
          </contact>
          <friction>
            <ode>
              <mu>0.6</mu>
              <mu2>0.6</mu2>
            </ode>
          </friction>
        </surface>
      </collision>
      <visual name='lower1_visual_visual'>
        <pose>0 0 0 0 -0 0</pose>
        <geometry>
          <mesh>
            <scale>1 1 1</scale>
            <uri>model://a1_description/meshes/calf.dae</uri>
          </mesh>
        </geometry>
      </visual>
      <visual name='lower1_fixed_joint_lump__toe1_visual_visual_1'>
        <pose>0 0 -0.213 0 -0 0</pose>
        <geometry>
          <sphere>
            <radius>0.01</radius>
          </sphere>
        </geometry>
        <material>
          <script>
            <name>Gazebo/DarkGrey</name>
            <uri>file://media/materials/scripts/gazebo.material</uri>
          </script>
        </material>
      </visual>
      <self_collide>0</self_collide>
      <sensor name='toe1_contact' type='contact'>
        <plugin name='toe1_plugin' filename='libgazebo_ros_bumper.so'>
          <alwaysOn>1</alwaysOn>
          <updateRate>500</updateRate>
          <bumperTopicName>gazebo/toe1_contact_state</bumperTopicName>
          <frameName>world</frameName>
        </plugin>
        <contact>
          <collision>lower1_collision_toe1</collision>
          <topic>__default_topic__</topic>
        </contact>
        <update_rate>500</update_rate>
        <pose>0 0 -0.213 0 -0 0</pose>
      </sensor>
      <self_collide>0</self_collide>
    </link>
    <plugin name='gazebo_ros_control' filename='libgazebo_ros_control.so'>
      <robotNamespace>/a1</robotNamespace>
      <robotSimType>gazebo_ros_control/DefaultRobotHWSim</robotSimType>
    </plugin>
    <plugin name='ground_truth_estimator' filename='libground_truth_estimator.so'>
      <updateRateHZ>500.0</updateRateHZ>
    </plugin>
    <static>0</static>
    <plugin name='gazebo_ros_force' filename='libgazebo_ros_force.so'>
      <topicName>/apply_force/trunk</topicName>
      <bodyName>body</bodyName>
      <xyzOffset>0 0 0</xyzOffset>
      <rpyOffset>0 -0 0</rpyOffset>
      <ignition::corrected_offsets>1</ignition::corrected_offsets>
    </plugin>
  </model>
</sdf>
