<sdf version='1.7'>
  <model name='a1'>
    <link name='base'>
      <inertial>
        <pose>0.020866 0.00186 -0.000469 0 -0 0</pose>
        <mass>5.56108</mass>
        <inertia>
          <ixx>0.0181527</ixx>
          <ixy>-0.000247078</ixy>
          <ixz>-0.000291004</ixz>
          <iyy>0.0680032</iyy>
          <iyz>-4.19233e-05</iyz>
          <izz>0.0774325</izz>
        </inertia>
      </inertial>
      <collision name='base_fixed_joint_lump__body_collision'>
        <pose>0 0 0 0 -0 0</pose>
        <geometry>
          <box>
            <size>0.3762 0.0935 0.114</size>
          </box>
        </geometry>
      </collision>
      <collision name='base_fixed_joint_lump__camera_chin_collision_1'>
        <pose>0.2522 0.0125 -0.0436 3.14159 1.5708 0</pose>
        <geometry>
          <box>
            <size>0.001 0.001 0.001</size>
          </box>
        </geometry>
        <surface>
          <contact>
            <ode/>
          </contact>
          <friction>
            <ode/>
          </friction>
        </surface>
      </collision>
      <collision name='base_fixed_joint_lump__camera_face_collision_2'>
        <pose>0.2785 0.0125 0.0167 3.14159 -0 0</pose>
        <geometry>
          <box>
            <size>0.001 0.001 0.001</size>
          </box>
        </geometry>
        <surface>
          <contact>
            <ode/>
          </contact>
          <friction>
            <ode/>
          </friction>
        </surface>
      </collision>
      <collision name='base_fixed_joint_lump__camera_left_collision_3'>
        <pose>-0.066 0.082 -0.0176 3.14159 0.2618 1.5708</pose>
        <geometry>
          <box>
            <size>0.001 0.001 0.001</size>
          </box>
        </geometry>
        <surface>
          <contact>
            <ode/>
          </contact>
          <friction>
            <ode/>
          </friction>
        </surface>
      </collision>
      <collision name='base_fixed_joint_lump__camera_rearDown_collision_4'>
        <pose>-0.0825 0.0125 -0.04365 3.14159 1.5708 0</pose>
        <geometry>
          <box>
            <size>0.001 0.001 0.001</size>
          </box>
        </geometry>
        <surface>
          <contact>
            <ode/>
          </contact>
          <friction>
            <ode/>
          </friction>
        </surface>
      </collision>
      <collision name='base_fixed_joint_lump__camera_right_collision_5'>
        <pose>-0.041 -0.082 -0.0176 3.14159 0.2618 -1.5708</pose>
        <geometry>
          <box>
            <size>0.001 0.001 0.001</size>
          </box>
        </geometry>
        <surface>
          <contact>
            <ode/>
          </contact>
          <friction>
            <ode/>
          </friction>
        </surface>
      </collision>
      <collision name='base_fixed_joint_lump__imu_link_collision_6'>
        <pose>-0.01592 -0.06659 -0.00617 0 -0 0</pose>
        <geometry>
          <box>
            <size>0.001 0.001 0.001</size>
          </box>
        </geometry>
        <surface>
          <contact>
            <ode/>
          </contact>
          <friction>
            <ode>
              <mu>0.2</mu>
              <mu2>0.2</mu2>
            </ode>
          </friction>
        </surface>
      </collision>
      <collision name='base_fixed_joint_lump__ultraSound_face_collision_7'>
        <pose>0.2747 0 -0.0088 0 -0 0</pose>
        <geometry>
          <box>
            <size>0.001 0.001 0.001</size>
          </box>
        </geometry>
      </collision>
      <collision name='base_fixed_joint_lump__ultraSound_left_collision_8'>
        <pose>-0.0535 0.0826 0.00868 0 0.2618 1.5708</pose>
        <geometry>
          <box>
            <size>0.001 0.001 0.001</size>
          </box>
        </geometry>
      </collision>
      <collision name='base_fixed_joint_lump__ultraSound_right_collision_9'>
        <pose>-0.0535 -0.0826 0.00868 0 0.2618 -1.5708</pose>
        <geometry>
          <box>
            <size>0.001 0.001 0.001</size>
          </box>
        </geometry>
      </collision>
      <visual name='base_visual'>
        <pose>0 0 0 0 -0 0</pose>
        <geometry>
          <box>
            <size>0.001 0.001 0.001</size>
          </box>
        </geometry>
        <material>
          <script>
            <name>Gazebo/Green</name>
            <uri>file://media/materials/scripts/gazebo.material</uri>
          </script>
        </material>
      </visual>
      <visual name='base_fixed_joint_lump__body_visual_1'>
        <pose>0 0 0 0 -0 0</pose>
        <geometry>
          <mesh>
            <scale>1 1 1</scale>
            <uri>model://a1_description/meshes/trunk.dae</uri>
          </mesh>
        </geometry>
      </visual>
      <visual name='base_fixed_joint_lump__0_hip_rotor_visual_2'>
        <pose>0.11215 0.04675 0 0 1.5708 0</pose>
        <geometry>
          <cylinder>
            <length>0.02</length>
            <radius>0.035</radius>
          </cylinder>
        </geometry>
      </visual>
      <visual name='base_fixed_joint_lump__1_hip_rotor_visual_3'>
        <pose>-0.11215 0.04675 0 0 1.5708 0</pose>
        <geometry>
          <cylinder>
            <length>0.02</length>
            <radius>0.035</radius>
          </cylinder>
        </geometry>
      </visual>
      <visual name='base_fixed_joint_lump__2_hip_rotor_visual_4'>
        <pose>0.11215 -0.04675 0 0 1.5708 0</pose>
        <geometry>
          <cylinder>
            <length>0.02</length>
            <radius>0.035</radius>
          </cylinder>
        </geometry>
      </visual>
      <visual name='base_fixed_joint_lump__3_hip_rotor_visual_5'>
        <pose>-0.11215 -0.04675 0 0 1.5708 0</pose>
        <geometry>
          <cylinder>
            <length>0.02</length>
            <radius>0.035</radius>
          </cylinder>
        </geometry>
      </visual>
      <visual name='base_fixed_joint_lump__camera_chin_visual_6'>
        <pose>0.2522 0.0125 -0.0436 3.14159 1.5708 0</pose>
        <geometry>
          <mesh>
            <scale>1 1 1</scale>
            <uri>model://a1_description/meshes/depthCamera.dae</uri>
          </mesh>
        </geometry>
      </visual>
      <visual name='base_fixed_joint_lump__camera_face_visual_7'>
        <pose>0.2785 0.0125 0.0167 3.14159 -0 0</pose>
        <geometry>
          <mesh>
            <scale>1 1 1</scale>
            <uri>model://a1_description/meshes/depthCamera.dae</uri>
          </mesh>
        </geometry>
      </visual>
      <visual name='base_fixed_joint_lump__camera_left_visual_8'>
        <pose>-0.066 0.082 -0.0176 3.14159 0.2618 1.5708</pose>
        <geometry>
          <mesh>
            <scale>1 1 1</scale>
            <uri>model://a1_description/meshes/depthCamera.dae</uri>
          </mesh>
        </geometry>
      </visual>
      <visual name='base_fixed_joint_lump__camera_rearDown_visual_9'>
        <pose>-0.0825 0.0125 -0.04365 3.14159 1.5708 0</pose>
        <geometry>
          <mesh>
            <scale>1 1 1</scale>
            <uri>model://a1_description/meshes/depthCamera.dae</uri>
          </mesh>
        </geometry>
      </visual>
      <visual name='base_fixed_joint_lump__camera_right_visual_10'>
        <pose>-0.041 -0.082 -0.0176 3.14159 0.2618 -1.5708</pose>
        <geometry>
          <mesh>
            <scale>1 1 1</scale>
            <uri>model://a1_description/meshes/depthCamera.dae</uri>
          </mesh>
        </geometry>
      </visual>
      <visual name='base_fixed_joint_lump__imu_link_visual_11'>
        <pose>-0.01592 -0.06659 -0.00617 0 -0 0</pose>
        <geometry>
          <box>
            <size>0.001 0.001 0.001</size>
          </box>
        </geometry>
        <material>
          <script>
            <name>Gazebo/Red</name>
            <uri>file://media/materials/scripts/gazebo.material</uri>
          </script>
        </material>
      </visual>
      <visual name='base_fixed_joint_lump__ultraSound_face_visual_12'>
        <pose>0.2747 0 -0.0088 0 -0 0</pose>
        <geometry>
          <mesh>
            <scale>1 1 1</scale>
            <uri>model://a1_description/meshes/ultraSound.dae</uri>
          </mesh>
        </geometry>
      </visual>
      <visual name='base_fixed_joint_lump__ultraSound_left_visual_13'>
        <pose>-0.0535 0.0826 0.00868 0 0.2618 1.5708</pose>
        <geometry>
          <mesh>
            <scale>1 1 1</scale>
            <uri>model://a1_description/meshes/ultraSound.dae</uri>
          </mesh>
        </geometry>
      </visual>
      <visual name='base_fixed_joint_lump__ultraSound_right_visual_14'>
        <pose>-0.0535 -0.0826 0.00868 0 0.2618 -1.5708</pose>
        <geometry>
          <mesh>
            <scale>1 1 1</scale>
            <uri>model://a1_description/meshes/ultraSound.dae</uri>
          </mesh>
        </geometry>
      </visual>
      <gravity>1</gravity>
      <sensor name='camera_chin_camera' type='depth'>
        <update_rate>16</update_rate>
        <camera>
          <horizontal_fov>2.094</horizontal_fov>
          <image>
            <width>928</width>
            <height>800</height>
            <format>R8G8B8</format>
          </image>
          <clip>
            <near>0.1</near>
            <far>5</far>
          </clip>
        </camera>
        <plugin name='camera_chin_controller' filename='libgazebo_ros_openni_kinect.so'>
          <baseline>0.025</baseline>
          <alwaysOn>1</alwaysOn>
          <updateRate>0.0</updateRate>
          <cameraName>camera_chin_ir</cameraName>
          <imageTopicName>/camera_chin/color/image_raw</imageTopicName>
          <cameraInfoTopicName>/camera_chin/color/camera_info</cameraInfoTopicName>
          <depthImageTopicName>/camera_chin/depth/image_raw</depthImageTopicName>
          <depthImageInfoTopicName>/camera_chin/depth/camera_info</depthImageInfoTopicName>
          <pointCloudTopicName>/cam2/point_cloud_chin</pointCloudTopicName>
          <frameName>camera_optical_chin</frameName>
          <pointCloudCutoff>0.1</pointCloudCutoff>
          <pointCloudCutoffMax>1.5</pointCloudCutoffMax>
          <distortionK1>0.0</distortionK1>
          <distortionK2>0.0</distortionK2>
          <distortionK3>0.0</distortionK3>
          <distortionT1>0.0</distortionT1>
          <distortionT2>0.0</distortionT2>
          <CxPrime>0</CxPrime>
          <Cx>0.0045</Cx>
          <Cy>0.0039</Cy>
          <focalLength>0</focalLength>
          <hackBaseline>0</hackBaseline>
        </plugin>
        <pose>0.2522 0.0125 -0.0436 3.14159 1.57079 3e-06</pose>
      </sensor>
      <sensor name='camera_face_camera' type='depth'>
        <update_rate>16</update_rate>
        <camera>
          <horizontal_fov>2.094</horizontal_fov>
          <image>
            <width>928</width>
            <height>800</height>
            <format>R8G8B8</format>
          </image>
          <clip>
            <near>0.1</near>
            <far>5</far>
          </clip>
        </camera>
        <plugin name='camera_face_controller' filename='libgazebo_ros_openni_kinect.so'>
          <baseline>0.025</baseline>
          <alwaysOn>1</alwaysOn>
          <updateRate>0.0</updateRate>
          <cameraName>camera_face_ir</cameraName>
          <imageTopicName>/camera_face/color/image_raw</imageTopicName>
          <cameraInfoTopicName>/camera_face/color/camera_info</cameraInfoTopicName>
          <depthImageTopicName>/camera_face/depth/image_raw</depthImageTopicName>
          <depthImageInfoTopicName>/camera_face/depth/camera_info</depthImageInfoTopicName>
          <pointCloudTopicName>/cam1/point_cloud_face</pointCloudTopicName>
          <frameName>camera_optical_face</frameName>
          <pointCloudCutoff>0.1</pointCloudCutoff>
          <pointCloudCutoffMax>1.5</pointCloudCutoffMax>
          <distortionK1>0.0</distortionK1>
          <distortionK2>0.0</distortionK2>
          <distortionK3>0.0</distortionK3>
          <distortionT1>0.0</distortionT1>
          <distortionT2>0.0</distortionT2>
          <CxPrime>0</CxPrime>
          <Cx>0.0045</Cx>
          <Cy>0.0039</Cy>
          <focalLength>0</focalLength>
          <hackBaseline>0</hackBaseline>
        </plugin>
        <pose>0.2785 0.0125 0.0167 3.14159 -0 0</pose>
      </sensor>
      <sensor name='camera_left_camera' type='depth'>
        <update_rate>16</update_rate>
        <camera>
          <horizontal_fov>2.094</horizontal_fov>
          <image>
            <width>928</width>
            <height>800</height>
            <format>R8G8B8</format>
          </image>
          <clip>
            <near>0.1</near>
            <far>5</far>
          </clip>
        </camera>
        <plugin name='camera_left_controller' filename='libgazebo_ros_openni_kinect.so'>
          <baseline>0.025</baseline>
          <alwaysOn>1</alwaysOn>
          <updateRate>0.0</updateRate>
          <cameraName>camera_left_ir</cameraName>
          <imageTopicName>/camera_left/color/image_raw</imageTopicName>
          <cameraInfoTopicName>/camera_left/color/camera_info</cameraInfoTopicName>
          <depthImageTopicName>/camera_left/depth/image_raw</depthImageTopicName>
          <depthImageInfoTopicName>/camera_left/depth/camera_info</depthImageInfoTopicName>
          <pointCloudTopicName>/cam3/point_cloud_left</pointCloudTopicName>
          <frameName>camera_optical_left</frameName>
          <pointCloudCutoff>0.1</pointCloudCutoff>
          <pointCloudCutoffMax>1.5</pointCloudCutoffMax>
          <distortionK1>0.0</distortionK1>
          <distortionK2>0.0</distortionK2>
          <distortionK3>0.0</distortionK3>
          <distortionT1>0.0</distortionT1>
          <distortionT2>0.0</distortionT2>
          <CxPrime>0</CxPrime>
          <Cx>0.0045</Cx>
          <Cy>0.0039</Cy>
          <focalLength>0</focalLength>
          <hackBaseline>0</hackBaseline>
        </plugin>
        <pose>-0.066 0.082 -0.0176 3.14159 0.2618 1.5708</pose>
      </sensor>
      <sensor name='camera_rearDown_camera' type='depth'>
        <update_rate>16</update_rate>
        <camera>
          <horizontal_fov>2.094</horizontal_fov>
          <image>
            <width>928</width>
            <height>800</height>
            <format>R8G8B8</format>
          </image>
          <clip>
            <near>0.1</near>
            <far>5</far>
          </clip>
        </camera>
        <plugin name='camera_rearDown_controller' filename='libgazebo_ros_openni_kinect.so'>
          <baseline>0.025</baseline>
          <alwaysOn>1</alwaysOn>
          <updateRate>0.0</updateRate>
          <cameraName>camera_rearDown_ir</cameraName>
          <imageTopicName>/camera_rearDown/color/image_raw</imageTopicName>
          <cameraInfoTopicName>/camera_rearDown/color/camera_info</cameraInfoTopicName>
          <depthImageTopicName>/camera_rearDown/depth/image_raw</depthImageTopicName>
          <depthImageInfoTopicName>/camera_rearDown/depth/camera_info</depthImageInfoTopicName>
          <pointCloudTopicName>/cam5/point_cloud_rearDown</pointCloudTopicName>
          <frameName>camera_optical_rearDown</frameName>
          <pointCloudCutoff>0.1</pointCloudCutoff>
          <pointCloudCutoffMax>1.5</pointCloudCutoffMax>
          <distortionK1>0.0</distortionK1>
          <distortionK2>0.0</distortionK2>
          <distortionK3>0.0</distortionK3>
          <distortionT1>0.0</distortionT1>
          <distortionT2>0.0</distortionT2>
          <CxPrime>0</CxPrime>
          <Cx>0.0045</Cx>
          <Cy>0.0039</Cy>
          <focalLength>0</focalLength>
          <hackBaseline>0</hackBaseline>
        </plugin>
        <pose>-0.0825 0.0125 -0.04365 3.14159 1.57079 3e-06</pose>
      </sensor>
      <sensor name='camera_right_camera' type='depth'>
        <update_rate>16</update_rate>
        <camera>
          <horizontal_fov>2.094</horizontal_fov>
          <image>
            <width>928</width>
            <height>800</height>
            <format>R8G8B8</format>
          </image>
          <clip>
            <near>0.1</near>
            <far>5</far>
          </clip>
        </camera>
        <plugin name='camera_right_controller' filename='libgazebo_ros_openni_kinect.so'>
          <baseline>0.025</baseline>
          <alwaysOn>1</alwaysOn>
          <updateRate>0.0</updateRate>
          <cameraName>camera_right_ir</cameraName>
          <imageTopicName>/camera_right/color/image_raw</imageTopicName>
          <cameraInfoTopicName>/camera_right/color/camera_info</cameraInfoTopicName>
          <depthImageTopicName>/camera_right/depth/image_raw</depthImageTopicName>
          <depthImageInfoTopicName>/camera_right/depth/camera_info</depthImageInfoTopicName>
          <pointCloudTopicName>/cam4/point_cloud_right</pointCloudTopicName>
          <frameName>camera_optical_right</frameName>
          <pointCloudCutoff>0.1</pointCloudCutoff>
          <pointCloudCutoffMax>1.5</pointCloudCutoffMax>
          <distortionK1>0.0</distortionK1>
          <distortionK2>0.0</distortionK2>
          <distortionK3>0.0</distortionK3>
          <distortionT1>0.0</distortionT1>
          <distortionT2>0.0</distortionT2>
          <CxPrime>0</CxPrime>
          <Cx>0.0045</Cx>
          <Cy>0.0039</Cy>
          <focalLength>0</focalLength>
          <hackBaseline>0</hackBaseline>
        </plugin>
        <pose>-0.041 -0.082 -0.0176 3.14159 0.2618 -1.5708</pose>
      </sensor>
      <gravity>1</gravity>
      <sensor name='imu_sensor' type='imu'>
        <always_on>1</always_on>
        <update_rate>1000</update_rate>
        <visualize>1</visualize>
        <topic>__default_topic__</topic>
        <plugin name='imu_plugin' filename='libgazebo_ros_imu_sensor.so'>
          <topicName>trunk_imu</topicName>
          <bodyName>imu_link</bodyName>
          <updateRateHZ>1000.0</updateRateHZ>
          <gaussianNoise>0.0</gaussianNoise>
          <xyzOffset>0 0 0</xyzOffset>
          <rpyOffset>0 0 0</rpyOffset>
          <frameName>imu_link</frameName>
        </plugin>
        <pose>-0.01592 -0.06659 -0.00617 0 -0 0</pose>
      </sensor>
    </link>
    <joint name='10' type='revolute'>
      <pose relative_to='base'>0.1881 -0.04675 0 0 -0 0</pose>
      <parent>base</parent>
      <child>hip2</child>
      <axis>
        <xyz>1 0 0</xyz>
        <limit>
          <lower>-0.863</lower>
          <upper>0.863</upper>
          <effort>23.7</effort>
          <velocity>30.1</velocity>
        </limit>
        <dynamics>
          <damping>0.01</damping>
          <friction>0.2</friction>
          <spring_reference>0</spring_reference>
          <spring_stiffness>0</spring_stiffness>
        </dynamics>
      </axis>
    </joint>
    <link name='hip2'>
      <pose relative_to='10'>0 0 0 0 -0 0</pose>
      <inertial>
        <pose>-0.004917 0.007626 -8.9e-05 0 -0 0</pose>
        <mass>0.68</mass>
        <inertia>
          <ixx>0.00039938</ixx>
          <ixy>1.45901e-05</ixy>
          <ixz>1.2461e-06</ixz>
          <iyy>0.000733419</iyy>
          <iyz>-1.57533e-06</iyz>
          <izz>0.000468422</izz>
        </inertia>
      </inertial>
      <collision name='hip2_collision'>
        <pose>0 -0.08 0 1.5708 -0 0</pose>
        <geometry>
          <cylinder>
            <length>0.04</length>
            <radius>0.046</radius>
          </cylinder>
        </geometry>
      </collision>
      <visual name='hip2_visual'>
        <pose>0 0 0 3.14159 -0 0</pose>
        <geometry>
          <mesh>
            <scale>1 1 1</scale>
            <uri>model://a1_description/meshes/hip.dae</uri>
          </mesh>
        </geometry>
      </visual>
      <visual name='hip2_fixed_joint_lump__2_thigh_rotor_visual_1'>
        <pose>0 0.00015 0 1.5708 -0 0</pose>
        <geometry>
          <cylinder>
            <length>0.02</length>
            <radius>0.035</radius>
          </cylinder>
        </geometry>
      </visual>
    </link>
    <joint name='4' type='revolute'>
      <pose relative_to='hip2'>0 -0.08 0 0 -0 0</pose>
      <parent>hip2</parent>
      <child>upper2</child>
      <axis>
        <xyz>0 1 0</xyz>
        <limit>
          <lower>-0.686</lower>
          <upper>4.501</upper>
          <effort>23.7</effort>
          <velocity>30.1</velocity>
        </limit>
        <dynamics>
          <damping>0.01</damping>
          <friction>0.2</friction>
          <spring_reference>0</spring_reference>
          <spring_stiffness>0</spring_stiffness>
        </dynamics>
      </axis>
    </joint>
    <link name='upper2'>
      <pose relative_to='4'>0 0 0 0 -0 0</pose>
      <inertial>
        <pose>-0.003047 0.019315 -0.0305 0 -0 0</pose>
        <mass>1.009</mass>
        <inertia>
          <ixx>0.0045988</ixx>
          <ixy>-6.13739e-05</ixy>
          <ixz>-0.000227529</ixz>
          <iyy>0.00468922</iyy>
          <iyz>-0.000610808</iyz>
          <izz>0.000817448</izz>
        </inertia>
      </inertial>
      <collision name='upper2_collision'>
        <pose>0 0 -0.1065 0 1.5708 0</pose>
        <geometry>
          <box>
            <size>0.213 0.0245 0.034</size>
          </box>
        </geometry>
      </collision>
      <visual name='upper2_visual'>
        <pose>0 0 0 0 -0 0</pose>
        <geometry>
          <mesh>
            <scale>1 1 1</scale>
            <uri>model://a1_description/meshes/thigh_mirror.dae</uri>
          </mesh>
        </geometry>
      </visual>
      <visual name='upper2_fixed_joint_lump__2_calf_rotor_visual_1'>
        <pose>0 0.03235 0 1.5708 -0 0</pose>
        <geometry>
          <cylinder>
            <length>0.02</length>
            <radius>0.035</radius>
          </cylinder>
        </geometry>
      </visual>
    </link>
    <joint name='5' type='revolute'>
      <pose relative_to='upper2'>0 0 -0.213 0 -0 0</pose>
      <parent>upper2</parent>
      <child>lower2</child>
      <axis>
        <xyz>0 1 0</xyz>
        <limit>
          <lower>-2.818</lower>
          <upper>-0.888</upper>
          <effort>35.55</effort>
          <velocity>20.06</velocity>
        </limit>
        <dynamics>
          <damping>0.01</damping>
          <friction>0.2</friction>
          <spring_reference>0</spring_reference>
          <spring_stiffness>0</spring_stiffness>
        </dynamics>
      </axis>
    </joint>
    <link name='lower2'>
      <pose relative_to='5'>0 0 0 0 -0 0</pose>
      <inertial>
        <pose>0.004299 0.000977 -0.146197 0 -0 0</pose>
        <mass>0.195862</mass>
        <inertia>
          <ixx>0.00148448</ixx>
          <ixy>-6.18827e-07</ixy>
          <ixz>-1.77209e-05</ixz>
          <iyy>0.00149764</iyy>
          <iyz>-3.56626e-06</iyz>
          <izz>3.60683e-05</izz>
        </inertia>
      </inertial>
      <collision name='lower2_collision'>
        <pose>0 0 -0.1065 0 1.5708 0</pose>
        <geometry>
          <box>
            <size>0.213 0.016 0.016</size>
          </box>
        </geometry>
      </collision>
      <collision name='lower2_fixed_joint_lump__toe2_collision_collision_1'>
        <pose>0 0 -0.213 0 -0 0</pose>
        <geometry>
          <sphere>
            <radius>0.02</radius>
          </sphere>
        </geometry>
      </collision>
      <visual name='lower2_visual'>
        <pose>0 0 0 0 -0 0</pose>
        <geometry>
          <mesh>
            <scale>1 1 1</scale>
            <uri>model://a1_description/meshes/calf.dae</uri>
          </mesh>
        </geometry>
      </visual>
      <visual name='lower2_fixed_joint_lump__toe2_visual_1'>
        <pose>0 0 -0.213 0 -0 0</pose>
        <geometry>
          <sphere>
            <radius>0.01</radius>
          </sphere>
        </geometry>
      </visual>
    </link>
    <joint name='11' type='revolute'>
      <pose relative_to='base'>-0.1881 -0.04675 0 0 -0 0</pose>
      <parent>base</parent>
      <child>hip3</child>
      <axis>
        <xyz>1 0 0</xyz>
        <limit>
          <lower>-0.863</lower>
          <upper>0.863</upper>
          <effort>23.7</effort>
          <velocity>30.1</velocity>
        </limit>
        <dynamics>
          <damping>0.01</damping>
          <friction>0.2</friction>
          <spring_reference>0</spring_reference>
          <spring_stiffness>0</spring_stiffness>
        </dynamics>
      </axis>
    </joint>
    <link name='hip3'>
      <pose relative_to='11'>0 0 0 0 -0 0</pose>
      <inertial>
        <pose>0.004917 0.007626 -8.9e-05 0 -0 0</pose>
        <mass>0.68</mass>
        <inertia>
          <ixx>0.00039938</ixx>
          <ixy>-1.45901e-05</ixy>
          <ixz>-1.2461e-06</ixz>
          <iyy>0.000733419</iyy>
          <iyz>-1.57533e-06</iyz>
          <izz>0.000468422</izz>
        </inertia>
      </inertial>
      <collision name='hip3_collision'>
        <pose>0 -0.08 0 1.5708 -0 0</pose>
        <geometry>
          <cylinder>
            <length>0.04</length>
            <radius>0.046</radius>
          </cylinder>
        </geometry>
      </collision>
      <visual name='hip3_visual'>
        <pose>0 0 0 -0 0 3.14159</pose>
        <geometry>
          <mesh>
            <scale>1 1 1</scale>
            <uri>model://a1_description/meshes/hip.dae</uri>
          </mesh>
        </geometry>
      </visual>
      <visual name='hip3_fixed_joint_lump__3_thigh_rotor_visual_1'>
        <pose>0 0.00015 0 1.5708 -0 0</pose>
        <geometry>
          <cylinder>
            <length>0.02</length>
            <radius>0.035</radius>
          </cylinder>
        </geometry>
      </visual>
    </link>
    <joint name='6' type='revolute'>
      <pose relative_to='hip3'>0 -0.08 0 0 -0 0</pose>
      <parent>hip3</parent>
      <child>upper3</child>
      <axis>
        <xyz>0 1 0</xyz>
        <limit>
          <lower>-0.686</lower>
          <upper>4.501</upper>
          <effort>23.7</effort>
          <velocity>30.1</velocity>
        </limit>
        <dynamics>
          <damping>0.01</damping>
          <friction>0.2</friction>
          <spring_reference>0</spring_reference>
          <spring_stiffness>0</spring_stiffness>
        </dynamics>
      </axis>
    </joint>
    <link name='upper3'>
      <pose relative_to='6'>0 0 0 0 -0 0</pose>
      <inertial>
        <pose>-0.003047 0.019315 -0.0305 0 -0 0</pose>
        <mass>1.009</mass>
        <inertia>
          <ixx>0.0045988</ixx>
          <ixy>-6.13739e-05</ixy>
          <ixz>-0.000227529</ixz>
          <iyy>0.00468922</iyy>
          <iyz>-0.000610808</iyz>
          <izz>0.000817448</izz>
        </inertia>
      </inertial>
      <collision name='upper3_collision'>
        <pose>0 0 -0.1065 0 1.5708 0</pose>
        <geometry>
          <box>
            <size>0.213 0.0245 0.034</size>
          </box>
        </geometry>
      </collision>
      <visual name='upper3_visual'>
        <pose>0 0 0 0 -0 0</pose>
        <geometry>
          <mesh>
            <scale>1 1 1</scale>
            <uri>model://a1_description/meshes/thigh_mirror.dae</uri>
          </mesh>
        </geometry>
      </visual>
      <visual name='upper3_fixed_joint_lump__3_calf_rotor_visual_1'>
        <pose>0 0.03235 0 1.5708 -0 0</pose>
        <geometry>
          <cylinder>
            <length>0.02</length>
            <radius>0.035</radius>
          </cylinder>
        </geometry>
      </visual>
    </link>
    <joint name='7' type='revolute'>
      <pose relative_to='upper3'>0 0 -0.213 0 -0 0</pose>
      <parent>upper3</parent>
      <child>lower3</child>
      <axis>
        <xyz>0 1 0</xyz>
        <limit>
          <lower>-2.818</lower>
          <upper>-0.888</upper>
          <effort>35.55</effort>
          <velocity>20.06</velocity>
        </limit>
        <dynamics>
          <damping>0.01</damping>
          <friction>0.2</friction>
          <spring_reference>0</spring_reference>
          <spring_stiffness>0</spring_stiffness>
        </dynamics>
      </axis>
    </joint>
    <link name='lower3'>
      <pose relative_to='7'>0 0 0 0 -0 0</pose>
      <inertial>
        <pose>0.004299 0.000977 -0.146197 0 -0 0</pose>
        <mass>0.195862</mass>
        <inertia>
          <ixx>0.00148448</ixx>
          <ixy>-6.18827e-07</ixy>
          <ixz>-1.77209e-05</ixz>
          <iyy>0.00149764</iyy>
          <iyz>-3.56626e-06</iyz>
          <izz>3.60683e-05</izz>
        </inertia>
      </inertial>
      <collision name='lower3_collision'>
        <pose>0 0 -0.1065 0 1.5708 0</pose>
        <geometry>
          <box>
            <size>0.213 0.016 0.016</size>
          </box>
        </geometry>
      </collision>
      <collision name='lower3_fixed_joint_lump__toe3_collision_collision_1'>
        <pose>0 0 -0.213 0 -0 0</pose>
        <geometry>
          <sphere>
            <radius>0.02</radius>
          </sphere>
        </geometry>
      </collision>
      <visual name='lower3_visual'>
        <pose>0 0 0 0 -0 0</pose>
        <geometry>
          <mesh>
            <scale>1 1 1</scale>
            <uri>model://a1_description/meshes/calf.dae</uri>
          </mesh>
        </geometry>
      </visual>
      <visual name='lower3_fixed_joint_lump__toe3_visual_1'>
        <pose>0 0 -0.213 0 -0 0</pose>
        <geometry>
          <sphere>
            <radius>0.01</radius>
          </sphere>
        </geometry>
      </visual>
    </link>
    <joint name='8' type='revolute'>
      <pose relative_to='base'>0.1881 0.04675 0 0 -0 0</pose>
      <parent>base</parent>
      <child>hip0</child>
      <axis>
        <xyz>1 0 0</xyz>
        <limit>
          <lower>-0.863</lower>
          <upper>0.863</upper>
          <effort>23.7</effort>
          <velocity>30.1</velocity>
        </limit>
        <dynamics>
          <damping>0.01</damping>
          <friction>0.2</friction>
          <spring_reference>0</spring_reference>
          <spring_stiffness>0</spring_stiffness>
        </dynamics>
      </axis>
    </joint>
    <link name='hip0'>
      <pose relative_to='8'>0 0 0 0 -0 0</pose>
      <inertial>
        <pose>-0.004917 -0.007626 -8.9e-05 0 -0 0</pose>
        <mass>0.68</mass>
        <inertia>
          <ixx>0.00039938</ixx>
          <ixy>-1.45901e-05</ixy>
          <ixz>1.2461e-06</ixz>
          <iyy>0.000733419</iyy>
          <iyz>1.57533e-06</iyz>
          <izz>0.000468422</izz>
        </inertia>
      </inertial>
      <collision name='hip0_collision'>
        <pose>0 0.08 0 1.5708 -0 0</pose>
        <geometry>
          <cylinder>
            <length>0.04</length>
            <radius>0.046</radius>
          </cylinder>
        </geometry>
      </collision>
      <visual name='hip0_visual'>
        <pose>0 0 0 0 -0 0</pose>
        <geometry>
          <mesh>
            <scale>1 1 1</scale>
            <uri>model://a1_description/meshes/hip.dae</uri>
          </mesh>
        </geometry>
      </visual>
      <visual name='hip0_fixed_joint_lump__0_thigh_rotor_visual_1'>
        <pose>0 -0.00015 0 1.5708 -0 0</pose>
        <geometry>
          <cylinder>
            <length>0.02</length>
            <radius>0.035</radius>
          </cylinder>
        </geometry>
      </visual>
    </link>
    <joint name='0' type='revolute'>
      <pose relative_to='hip0'>0 0.08 0 0 -0 0</pose>
      <parent>hip0</parent>
      <child>upper0</child>
      <axis>
        <xyz>0 1 0</xyz>
        <limit>
          <lower>-0.686</lower>
          <upper>4.501</upper>
          <effort>23.7</effort>
          <velocity>30.1</velocity>
        </limit>
        <dynamics>
          <damping>0.01</damping>
          <friction>0.2</friction>
          <spring_reference>0</spring_reference>
          <spring_stiffness>0</spring_stiffness>
        </dynamics>
      </axis>
    </joint>
    <link name='upper0'>
      <pose relative_to='0'>0 0 0 0 -0 0</pose>
      <inertial>
        <pose>-0.003047 -0.019315 -0.0305 0 -0 0</pose>
        <mass>1.009</mass>
        <inertia>
          <ixx>0.0045988</ixx>
          <ixy>6.13739e-05</ixy>
          <ixz>-0.000227529</ixz>
          <iyy>0.00468922</iyy>
          <iyz>0.000610808</iyz>
          <izz>0.000817448</izz>
        </inertia>
      </inertial>
      <collision name='upper0_collision'>
        <pose>0 0 -0.1065 0 1.5708 0</pose>
        <geometry>
          <box>
            <size>0.213 0.0245 0.034</size>
          </box>
        </geometry>
      </collision>
      <visual name='upper0_visual'>
        <pose>0 0 0 0 -0 0</pose>
        <geometry>
          <mesh>
            <scale>1 1 1</scale>
            <uri>model://a1_description/meshes/thigh.dae</uri>
          </mesh>
        </geometry>
      </visual>
      <visual name='upper0_fixed_joint_lump__0_calf_rotor_visual_1'>
        <pose>0 -0.03235 0 1.5708 -0 0</pose>
        <geometry>
          <cylinder>
            <length>0.02</length>
            <radius>0.035</radius>
          </cylinder>
        </geometry>
      </visual>
    </link>
    <joint name='1' type='revolute'>
      <pose relative_to='upper0'>0 0 -0.213 0 -0 0</pose>
      <parent>upper0</parent>
      <child>lower0</child>
      <axis>
        <xyz>0 1 0</xyz>
        <limit>
          <lower>-2.818</lower>
          <upper>-0.888</upper>
          <effort>35.55</effort>
          <velocity>20.06</velocity>
        </limit>
        <dynamics>
          <damping>0.01</damping>
          <friction>0.2</friction>
          <spring_reference>0</spring_reference>
          <spring_stiffness>0</spring_stiffness>
        </dynamics>
      </axis>
    </joint>
    <link name='lower0'>
      <pose relative_to='1'>0 0 0 0 -0 0</pose>
      <inertial>
        <pose>0.004299 0.000977 -0.146197 0 -0 0</pose>
        <mass>0.195862</mass>
        <inertia>
          <ixx>0.00148448</ixx>
          <ixy>-6.18827e-07</ixy>
          <ixz>-1.77209e-05</ixz>
          <iyy>0.00149764</iyy>
          <iyz>-3.56626e-06</iyz>
          <izz>3.60683e-05</izz>
        </inertia>
      </inertial>
      <collision name='lower0_collision'>
        <pose>0 0 -0.1065 0 1.5708 0</pose>
        <geometry>
          <box>
            <size>0.213 0.016 0.016</size>
          </box>
        </geometry>
      </collision>
      <collision name='lower0_fixed_joint_lump__toe0_collision_collision_1'>
        <pose>0 0 -0.213 0 -0 0</pose>
        <geometry>
          <sphere>
            <radius>0.02</radius>
          </sphere>
        </geometry>
      </collision>
      <visual name='lower0_visual'>
        <pose>0 0 0 0 -0 0</pose>
        <geometry>
          <mesh>
            <scale>1 1 1</scale>
            <uri>model://a1_description/meshes/calf.dae</uri>
          </mesh>
        </geometry>
      </visual>
      <visual name='lower0_fixed_joint_lump__toe0_visual_1'>
        <pose>0 0 -0.213 0 -0 0</pose>
        <geometry>
          <sphere>
            <radius>0.01</radius>
          </sphere>
        </geometry>
      </visual>
    </link>
    <joint name='9' type='revolute'>
      <pose relative_to='base'>-0.1881 0.04675 0 0 -0 0</pose>
      <parent>base</parent>
      <child>hip1</child>
      <axis>
        <xyz>1 0 0</xyz>
        <limit>
          <lower>-0.863</lower>
          <upper>0.863</upper>
          <effort>23.7</effort>
          <velocity>30.1</velocity>
        </limit>
        <dynamics>
          <damping>0.01</damping>
          <friction>0.2</friction>
          <spring_reference>0</spring_reference>
          <spring_stiffness>0</spring_stiffness>
        </dynamics>
      </axis>
    </joint>
    <link name='hip1'>
      <pose relative_to='9'>0 0 0 0 -0 0</pose>
      <inertial>
        <pose>0.004917 -0.007626 -8.9e-05 0 -0 0</pose>
        <mass>0.68</mass>
        <inertia>
          <ixx>0.00039938</ixx>
          <ixy>1.45901e-05</ixy>
          <ixz>-1.2461e-06</ixz>
          <iyy>0.000733419</iyy>
          <iyz>1.57533e-06</iyz>
          <izz>0.000468422</izz>
        </inertia>
      </inertial>
      <collision name='hip1_collision'>
        <pose>0 0.08 0 1.5708 -0 0</pose>
        <geometry>
          <cylinder>
            <length>0.04</length>
            <radius>0.046</radius>
          </cylinder>
        </geometry>
      </collision>
      <visual name='hip1_visual'>
        <pose>0 0 0 3.14159 0 3.14159</pose>
        <geometry>
          <mesh>
            <scale>1 1 1</scale>
            <uri>model://a1_description/meshes/hip.dae</uri>
          </mesh>
        </geometry>
      </visual>
      <visual name='hip1_fixed_joint_lump__1_thigh_rotor_visual_1'>
        <pose>0 -0.00015 0 1.5708 -0 0</pose>
        <geometry>
          <cylinder>
            <length>0.02</length>
            <radius>0.035</radius>
          </cylinder>
        </geometry>
      </visual>
    </link>
    <joint name='2' type='revolute'>
      <pose relative_to='hip1'>0 0.08 0 0 -0 0</pose>
      <parent>hip1</parent>
      <child>upper1</child>
      <axis>
        <xyz>0 1 0</xyz>
        <limit>
          <lower>-0.686</lower>
          <upper>4.501</upper>
          <effort>23.7</effort>
          <velocity>30.1</velocity>
        </limit>
        <dynamics>
          <damping>0.01</damping>
          <friction>0.2</friction>
          <spring_reference>0</spring_reference>
          <spring_stiffness>0</spring_stiffness>
        </dynamics>
      </axis>
    </joint>
    <link name='upper1'>
      <pose relative_to='2'>0 0 0 0 -0 0</pose>
      <inertial>
        <pose>-0.003047 -0.019315 -0.0305 0 -0 0</pose>
        <mass>1.009</mass>
        <inertia>
          <ixx>0.0045988</ixx>
          <ixy>6.13739e-05</ixy>
          <ixz>-0.000227529</ixz>
          <iyy>0.00468922</iyy>
          <iyz>0.000610808</iyz>
          <izz>0.000817448</izz>
        </inertia>
      </inertial>
      <collision name='upper1_collision'>
        <pose>0 0 -0.1065 0 1.5708 0</pose>
        <geometry>
          <box>
            <size>0.213 0.0245 0.034</size>
          </box>
        </geometry>
      </collision>
      <visual name='upper1_visual'>
        <pose>0 0 0 0 -0 0</pose>
        <geometry>
          <mesh>
            <scale>1 1 1</scale>
            <uri>model://a1_description/meshes/thigh.dae</uri>
          </mesh>
        </geometry>
      </visual>
      <visual name='upper1_fixed_joint_lump__1_calf_rotor_visual_1'>
        <pose>0 -0.03235 0 1.5708 -0 0</pose>
        <geometry>
          <cylinder>
            <length>0.02</length>
            <radius>0.035</radius>
          </cylinder>
        </geometry>
      </visual>
    </link>
    <joint name='3' type='revolute'>
      <pose relative_to='upper1'>0 0 -0.213 0 -0 0</pose>
      <parent>upper1</parent>
      <child>lower1</child>
      <axis>
        <xyz>0 1 0</xyz>
        <limit>
          <lower>-2.818</lower>
          <upper>-0.888</upper>
          <effort>35.55</effort>
          <velocity>20.06</velocity>
        </limit>
        <dynamics>
          <damping>0.01</damping>
          <friction>0.2</friction>
          <spring_reference>0</spring_reference>
          <spring_stiffness>0</spring_stiffness>
        </dynamics>
      </axis>
    </joint>
    <link name='lower1'>
      <pose relative_to='3'>0 0 0 0 -0 0</pose>
      <inertial>
        <pose>0.004299 0.000977 -0.146197 0 -0 0</pose>
        <mass>0.195862</mass>
        <inertia>
          <ixx>0.00148448</ixx>
          <ixy>-6.18827e-07</ixy>
          <ixz>-1.77209e-05</ixz>
          <iyy>0.00149764</iyy>
          <iyz>-3.56626e-06</iyz>
          <izz>3.60683e-05</izz>
        </inertia>
      </inertial>
      <collision name='lower1_collision'>
        <pose>0 0 -0.1065 0 1.5708 0</pose>
        <geometry>
          <box>
            <size>0.213 0.016 0.016</size>
          </box>
        </geometry>
      </collision>
      <collision name='lower1_fixed_joint_lump__toe1_collision_collision_1'>
        <pose>0 0 -0.213 0 -0 0</pose>
        <geometry>
          <sphere>
            <radius>0.02</radius>
          </sphere>
        </geometry>
      </collision>
      <visual name='lower1_visual'>
        <pose>0 0 0 0 -0 0</pose>
        <geometry>
          <mesh>
            <scale>1 1 1</scale>
            <uri>model://a1_description/meshes/calf.dae</uri>
          </mesh>
        </geometry>
      </visual>
      <visual name='lower1_fixed_joint_lump__toe1_visual_1'>
        <pose>0 0 -0.213 0 -0 0</pose>
        <geometry>
          <sphere>
            <radius>0.01</radius>
          </sphere>
        </geometry>
      </visual>
    </link>
    <plugin name='gazebo_ros_control' filename='libgazebo_ros_control.so'>
      <robotNamespace>/a1_gazebo</robotNamespace>
      <robotSimType>gazebo_ros_control/DefaultRobotHWSim</robotSimType>
    </plugin>
    <plugin name='3dplot' filename='libLinkPlot3DPlugin.so'>
      <frequency>10</frequency>
      <plot>
        <link>base</link>
        <pose>0 0 0 0 0 0</pose>
        <material>Gazebo/Yellow</material>
      </plot>
    </plugin>
    <static>0</static>
    <plugin name='gazebo_ros_force' filename='libgazebo_ros_force.so'>
      <topicName>/apply_force/trunk</topicName>
      <bodyName>base</bodyName>
      <xyzOffset>0 0 0</xyzOffset>
      <rpyOffset>0 -0 0</rpyOffset>
    </plugin>
  </model>
</sdf>
